#VRML_SIM R2021a utf8
WorldInfo {
}
Viewpoint {
  orientation 0 1 0 0
  position 6.180259869843676e-05 -2.4691933415396127e-07 16.444831044310305
}
TexturedBackground {
}
TexturedBackgroundLight {
}
RectangleArena {
  rotation 1 0 0 1.5708
  floorSize 10 10
}
DEF Supervisor Robot {
  controller "openDoor"
  supervisor TRUE
}
DEF DOOR1 Door {
  translation -2.5 -4.25 0
  rotation 0.5773509358554485 0.5773489358556708 0.5773509358554485 2.0944
  name "door1"
  size 1.5 2.4 0.2
  position -1.570000000340288
}
DEF DOOR2 Door {
  translation -1.125 2.75 0
  rotation 1 0 0 1.5708
  name "door2"
  size 1.25 2.4 0.2
  position -4.397212286874786e-08
}
Wall {
  translation -4 -2.75 1.23289e-06
  rotation 0.5773509358554485 0.5773489358556708 0.5773509358554485 2.0944
  size 2.5 2 0.1
}
Wall {
  translation -3.25 -1.5 0
  rotation 1 0 0 1.5708
  name "wall(1)"
  size 1.5 2 0.1
}
Wall {
  translation -2.5 -2.5 0
  rotation 0.5773509358554485 0.5773489358556708 0.5773509358554485 2.0944
  name "wall(2)"
  size 2 2 0.1
}
Wall {
  translation -1 -3 0
  rotation 1 0 0 1.5708
  name "wall(4)"
  size 3 2 0.1
}
Wall {
  translation 0 -1.5 0
  rotation 1.6952594753969508e-09 0.707104781184338 0.7071087811831002 -3.1415853071795863
  name "wall(7)"
  size 3 2 0.1
}
Wall {
  translation 2 3.75 0
  rotation 1.6952594753969508e-09 0.707104781184338 0.7071087811831002 -3.1415853071795863
  name "wall(8)"
  size 2 2 0.1
}
Wall {
  translation 4 2.75 0
  rotation 1.6952594753969508e-09 0.707104781184338 0.7071087811831002 -3.1415853071795863
  name "wall(9)"
  size 2 2 0.1
}
Wall {
  translation 0.5 2.75 0
  rotation 1.6952594753969508e-09 0.707104781184338 0.7071087811831002 -3.1415853071795863
  name "wall(11)"
  size 2 2 0.1
}
Wall {
  translation 3 3.25 0
  rotation 0.5773509358554485 0.5773489358556708 0.5773509358554485 2.0944
  name "wall(12)"
  size 1 2 0.1
}
Wall {
  translation 2.5 1.25 0
  rotation 1.6952594753969508e-09 0.707104781184338 0.7071087811831002 -3.1415853071795863
  name "wall(13)"
  size 2 2 0.1
}
Wall {
  translation 1.5 -0.5 0
  rotation 0.5773509358554485 0.5773489358556708 0.5773509358554485 2.0944
  name "wall(14)"
  size 6.5 2 0.1
}
Wall {
  translation 2.5 -3.75 0
  rotation 1.6952594753969508e-09 0.707104781184338 0.7071087811831002 -3.1415853071795863
  name "wall(15)"
  size 2 2 0.1
}
Wall {
  translation 3.5 -2.75 0
  rotation 0.5773509358554485 0.5773489358556708 0.5773509358554485 2.0944
  name "wall(16)"
  size 2 2 0.1
}
Wall {
  translation 4 -0.25 0
  rotation 1.6952594753969508e-09 0.707104781184338 0.7071087811831002 -3.1415853071795863
  name "wall(21)"
  size 2 2 0.1
}
Wall {
  translation -2.25 0.5 0
  rotation 1.6952594753969508e-09 0.707104781184338 0.7071087811831002 -3.1415853071795863
  name "wall(22)"
  size 3.5 2 0.1
}
Wall {
  translation -1.75 3.5 0
  rotation 0.5773509358554485 0.5773489358556708 0.5773509358554485 2.0944
  name "wall(23)"
  size 3 2 0.1
}
Wall {
  translation -2.25 2 0
  rotation 1.6952594753969508e-09 0.707104781184338 0.7071087811831002 -3.1415853071795863
  name "wall(25)"
  size 1 2 0.1
}
Wall {
  translation -4 2.75 0
  rotation 0.5773509358554485 0.5773489358556708 0.5773509358554485 2.0944
  name "wall(26)"
  size 2 2 0.1
}
Wall {
  translation -4 3.75 0
  rotation 1.6952594753969508e-09 0.707104781184338 0.7071087811831002 -3.1415853071795863
  name "wall(27)"
  size 2 2 0.1
}
Wall {
  translation -4 0 0
  rotation 0.5773509358554485 0.5773489358556708 0.5773509358554485 2.0944
  name "wall(29)"
  size 1 2 0.1
}
Robot {
  translation 4.595109295971558 4.645399373525587 0.021456433155918914
  rotation 0.0025104974246988906 8.767673617701048e-05 0.9999968448527576 3.1369301198799
  scale 1.3 1.3 1.3
  children [
    Transform {
      translation 0.15 1.52942e-07 0.01
      rotation 0 0 1 -1.5707953071795862
      children [
        Shape {
          appearance PBRAppearance {
          }
          geometry Cone {
            bottomRadius 0.05
            height 0.1
          }
        }
      ]
    }
    Transform {
      translation -0.15 -2.06014e-07 0.01
      rotation 0 0 1 1.5708
      children [
        Shape {
          appearance PBRAppearance {
          }
          geometry Cone {
            bottomRadius 0.05
            height 0.1
          }
        }
      ]
    }
    GPS {
      translation 0.08 0 0.04
      children [
        Shape {
          appearance DryMud {
          }
          geometry Box {
            size 0.01 0.01 0.01
          }
        }
      ]
      name "front_gps"
    }
    GPS {
      translation -0.08 0 0.04
      children [
        Shape {
          appearance DryMud {
          }
          geometry Box {
            size 0.01 0.01 0.01
          }
        }
      ]
      name "back_gps"
    }
    GPS {
      translation 0 0 0.04
      scale 0.1 0.1 0.1
      children [
        Shape {
          appearance Appearance {
          }
          geometry Box {
            size 0.1 0.1 0.1
          }
        }
      ]
      name "car_gps"
    }
    Lidar {
      translation 8.36469e-08 -2.56852e-07 0.11
      rotation 0.5773509358554485 0.5773489358556708 0.5773509358554485 2.0943999999999994
      fieldOfView 3.14
      numberOfLayers 1
      maxRange 5
      type "rotating"
    }
    InertialUnit {
      rotation 0 0 1 1.5708
    }
    HingeJoint {
      jointParameters HingeJointParameters {
        position 44.78737519903293
        axis 0 1 0
        anchor 0.06 0.07 0
      }
      device [
        RotationalMotor {
          name "motor1"
          maxVelocity 50
        }
      ]
      endPoint Solid {
        translation 0.05991698411085016 0.0700224339187765 2.8441376338494172e-05
        rotation -0.007654843659583188 -0.9996651710969714 0.024717383846402426 6.14913703899246
        children [
          DEF WHEEL Shape {
            geometry Cylinder {
              height 0.03
              radius 0.04
            }
          }
        ]
        boundingObject USE WHEEL
        physics Physics {
        }
      }
    }
    HingeJoint {
      jointParameters HingeJointParameters {
        position 44.78737401353289
        axis 0 1 0
        anchor -0.06 0.07 0
      }
      device [
        RotationalMotor {
          name "motor2"
          maxVelocity 50
        }
      ]
      endPoint Solid {
        translation -0.05992808081228021 0.07001803352533087 -4.607179791551773e-05
        rotation -0.007655042737795607 -0.9996651467876694 0.024718305335718192 6.149138126462363
        children [
          Shape {
            geometry Cylinder {
              height 0.03
              radius 0.04
            }
          }
        ]
        name "solid(1)"
        boundingObject USE WHEEL
        physics Physics {
        }
      }
    }
    HingeJoint {
      jointParameters HingeJointParameters {
        position 33.59613508057187
        axis 0 1 0
        anchor 0.06 -0.07 0
      }
      device [
        RotationalMotor {
          name "motor3"
          maxVelocity 50
        }
      ]
      endPoint Solid {
        translation 0.05993876551036807 -0.07002126999800695 5.721855662436007e-05
        rotation -0.000962015724840189 -0.9999995364113222 -4.126603641933268e-05 4.8737764198802065
        children [
          Shape {
            geometry Cylinder {
              height 0.03
              radius 0.04
            }
          }
        ]
        name "solid(2)"
        boundingObject USE WHEEL
        physics Physics {
        }
      }
    }
    HingeJoint {
      jointParameters HingeJointParameters {
        position 33.59613257123246
        axis 0 1 0
        anchor -0.06 -0.07 0
      }
      device [
        RotationalMotor {
          name "motor4"
          maxVelocity 50
        }
      ]
      endPoint Solid {
        translation -0.05992921288645339 -0.07001986402761418 -4.872596992100366e-05
        rotation -0.0009619596524680207 -0.9999995364619051 -4.1347331819986793e-05 4.873778837350244
        children [
          Shape {
            geometry Cylinder {
              height 0.03
              radius 0.04
            }
          }
        ]
        name "solid(3)"
        boundingObject USE WHEEL
        physics Physics {
        }
      }
    }
    DEF BODY Shape {
      appearance PBRAppearance {
      }
      geometry Box {
        size 0.2 0.1 0.05
      }
    }
  ]
  name "robot(1)"
  boundingObject USE BODY
  physics Physics {
    density -1
    mass 10
  }
  controller "controller3"
}
